Workbook

Sheet Portuguese
B1: titulo | C1: ingredientes | D1: preparo | E1: url
A2: 0 | B2: Bolo de cenoura | C2: 1/2 xícara (chá) de óleo 3 cenouras médias raladas 4 ovos 2 xícaras (chá) de açúcar 2 e 1/2 xícaras (chá) de farinha de trigo 1 colher (sopa) de fermento em pó 1 colher (sopa) de manteiga 3 colheres (sopa) de chocolate em pó 1 xícara (chá) de açúcar 1 xícara (chá) de leite | D2: Em um liquidificador, adicione a cenoura, os ovos e o óleo, depois misture. Acrescente o açúcar e bata novamente por 5 minutos. Em uma tigela ou na batedeira, adicione a farinha de trigo e depoismisture novamente. Acrescente o fermento e misture lentamente com uma colher. Asse em um forno preaquecido a 180° C por aproximadamente 40 minutos. Despeje em uma tigela a manteiga, o chocolate em pó, o açúcar e o leite, depois misture. Leve a mistura ao fogo e continue misturando até obter uma consistência cremosa, depois despeje acalda por cima do bolo. | E2: https://www.tudogostoso.com.br/receita/23-bolo-de-cenoura.html
A3: 1 | B3: Bolo gelado | C3: 4 ovos 2 xícaras (chá) de açúcar 3 xícaras (chá) de farinha de trigo 1 copo (americano) de suco de laranja 1 colher (sopa) de fermento em pó 1 garrafa pequena de leite de coco 1 garrafa de leite (utilize a mesma garrafa do leite de coco como medida) 1 lata de leite condensado 1 pacote de coco ralado sem açúcar | D3: Em uma batedeira, bata as claras em neve acrescentando o açúcar aos poucos e bata por 3 minutos. Adicione as gemas, o trigo, o suco e continue batendo até formar uma massa homogênea. Por último, adicione o fermento e bata por mais 40 segundos na menor velocidade da batedeira. Despeje a massa em uma forma média e untada. Asse em forno preaquecido em temperatura média de 180 °C por 40 minutos ou até dourar. Em uma tigela, misture o leite de coco, o leite, o leite condensado e reserve. Após 40 minutos, retire o bolo do forno e fure toda a sua superfície com um garfo para facilitar a penetração da cobertura. Com o bolo ainda quente, despeje a cobertura sobre ele e salpique por cima o coco ralado. Leve a geladeira por 3 horas, depois corte o bolo em quadrados do tamanho que preferir e embrulhe com papel alumínio. Conserve na geladeira. | E3: https://www.tudogostoso.com.br/receita/2313-bolo-gelado.html
A4: 2 | B4: Torta de liquidificador | C4: 1 ovo 6 colheres (sopa) de farinha de trigo 5 colheres (sopa) de queijo ralado 1 pitada de orégano 1 colher (sobremesa) de fermento em pó 1/2 cebola 1 xícara (chá) de leite 1/2 xícara (chá) de óleo 1 pitada de sal | D4: Bata todos os ingredientes no liquidificador até que a massa esteja firme e encorpada. Para uma massa mais consistente, acrescente mais uma porção de farinha de trigo. Unte uma forma com óleo e despeje metade da massa até cobrir todo o fundo. Em seguida, acrescente um recheio de sua escolha e cubra com o restante da massa. Asse em forno médio (180° C), preaquecido, por 30 minutos. | E4: https://www.tudogostoso.com.br/receita/1362-torta-de-liquidificador.html
A5: 3 | B5: Fricassê de frango | C5: 1 lata de creme de leite 1 lata de milho verde 1 copo de requeijão cremoso 100 g de azeitona sem caroço 2 peitos de frango desfiados 200 g de mussarela fatiada 100 g de batata palha 1 xícara de água 1 pitada de sal | D5: Bata no liquidificador o milho, o requeijão, o creme de leite e a água. Refogue o creme do liquidificador com o frango desfiado, as azeitonas e o sal até ficar com uma textura espessa. Coloque o refogado numa assadeira, cubra com mussarela e espalhe a batata palha por cima. Leve ao forno até borbulhar. Sirvacom arroz branco. | E5: https://www.tudogostoso.com.br/receita/10254-fricasse-de-frango.html
A6: 4 | B6: Bolo de chocolate molhadinho | C6: 2 xícaras de farinha de trigo 2 xícaras de açúcar 1 xícara de leite 6 colheres (sopa) de chocolate em pó 1 colher (sopa) de fermento em pó 6 ovos Cobertura 2 colheres (sopa) de manteiga 2 xícaras de leite 1 xícara de chocolate em pó | D6: Em uma batedeira, bata as claras em neve. Acrescente as gemas, o açúcar e bata novamente. Adicione a farinha, o chocolate em pó, o fermento, o leite e bata por mais alguns minutos. Despeje a massa em uma forma untada e leve para assar em forno médio (180° C), preaquecido, por 40 minutos. Em uma panela, leve a fogo médio o chocolate em pó, a manteiga e o leite, deixe até ferver. Despeje quente sobre o bolo já assado. | E6: https://www.tudogostoso.com.br/receita/951-bolo-de-chocolate-molhadinho.html
A7: 5 | B7: Panqueca de carne moída | C7: 1 e 1/2 xícara (chá) de farinha de trigo 1 xícara (chá) de leite 2 ovos 4 colheres (sopa) de óleo sal a gosto 300 g de carne moída 2 colheres (sopa) de cebola picada ou ralada 1/2 tomate cortado em cubos 1/2 lata de extrato de tomate 1 caixa de creme de leite sal a gosto 400 g de muçarela fatiado queijo ralado a gosto | D7: Bata no liquidificador os ovos, o leite, o óleo, e acrescente a farinha de trigo aos poucos. Após acrescentar toda a farinha de trigo, adicione sal a gosto. Misture a massa até obter uma consistência cremosa. Com um papel-toalha, espalhe óleo por toda a frigideira e despeje uma concha de massa. Faça movimentos circulares para que a massa se espalhepor toda a frigideira. Espere até a massa soltar do fundo e vire a massa para fritar do outro lado. Em uma panela, doure a cebola com o óleo e acrescente a carne. Deixe cozinhar até que saia água da carne, diminua o fogo e tampe. Acrescente o tomate picado e tampe novamente. Deixe cozinhar por mais 3 minutos e misture. Acrescenteo extrato de tomatee temperos a gosto. Deixe cozinhar por mais 10 minutos. Quando o molho engrossar, desligue o fogo. Deixe esfriar o molho, acrescente o creme de leite e misture bem. Quando estiver bem homogêneo, leve novamente ao fogo e deixe cozinhar em fogo baixo por mais 5 minutos. Recheie a panqueca com uma fatia de mussarela, uma porção de carne e enrole. Faça esse processo com todas as panquecas. Despeje um pouco de caldo no fundo de um refratário,para untar. Disponha as panquecas já prontas no refratário e despeje sobre elas o restante do molho. Polvilhe queijo ralado sobre as panquecas. Leve ao forno para gratinar, em fogo médio, por 20 minutos ou até que o queijo esteja derretido. | E7: https://www.tudogostoso.com.br/receita/760-panqueca-de-carne-moida.html
A8: 6 | B8: Pudim de leite condensado simples | C8: 1 lata de leite condensado 1 xícara de leite de vaca 4 ovos inteiros 1 xícara (chá) de açúcar 1/3 de xícara (chá) de água | D8: Em uma panela, misture a água e o açúcar até formar uma calda. Unte uma forma com a calda e reserve. Bata todos os ingredientes no liquidificador e despeje na forma caramelizada. Leve para assar em banho-maria por 40 minutos. Desenforme e sirva. | E8: https://www.tudogostoso.com.br/receita/3687-pudim-de-leite-condensado.html
A9: 7 | B9: Bolo simples | C9: 2 xícaras (chá) de açúcar 3 xícaras (chá) de farinha de trigo 4 colheres (sopa) de margarina 3 ovos 1 e 1/2 xícara (chá) de leite 1 colher (sopa) bem cheia de fermento em pó | D9: Bata as claras em nevee reserve. Misture as gemas, a margarina e o açúcaraté obter uma massa homogênea. Acrescente o leite e a farinha de trigo aos poucos, sem parar de bater. Por último, adicione as claras em neve e o fermento. Despeje a massa em uma forma grande de furo centraluntada e enfarinhada. Asse em forno médio 180 °C, preaquecido, por aproximadamente 40 minutos ou ao furar o bolo com um garfo, este saia limpo. | E9: https://www.tudogostoso.com.br/receita/29124-bolo-simples.html
A10: 8 | B10: Bolinho de chuva | C10: 2 ovos 2 colheres (sopa) de açúcar 1 xícara (chá) de leite 2 e 1/2 xícaras (chá) de farinha de trigo 1 colher (sopa) de fermento 3 colheres (sopa) de açúcar 1 colher (chá) de canela | D10: Em um recipiente, adicione os ovos, o açúcar, o leite, a farinha de trigo e o fermento, depois misture-os até obter uma massa lisa e homogênea. Com a ajuda de uma colher, pegue porções da mistura e despeje em uma panela com o óleo quente. Retire do fogo quando estiver no ponto, depois misture a canela com açúcar e salpique no bolinho de chuva já frito. | E10: https://www.tudogostoso.com.br/receita/4683-bolinho-de-chuva.html
A11: 9 | B11: Torta de frango | C11: 500 g de peito de frango sem pele 1/2 litro de caldo de galinha 4 colheres (sopa) de óleo 1 dente de alho amassado 1 cebola picada 3 tomates sem pele e sem sementes 1 xícara (chá) de ervilhas sal a gosto pimenta-do-reino a gosto 250 ml de leite 3/4 de xícara (chá) de óleo 2 ovos 1 e 1/2 xícara (chá) de farinha de trigo sal a gosto 1 colher (sopa) de fermento em pó queijo ralado a gosto | D11: Cozinhe o peito de frango no caldo até ficar macio. Separe 1 xícara (chá) de caldo do cozimento e reserve. Refogue os demais ingredientes e acrescente as ervilhas por último. Desfie o frango, misture ao caldo e deixe cozinhar até secar. Bata o leite, o óleo e os ovos no liquidificador em velocidade baixa. Acrescente aos poucos a farinha, o sal e o fermento. Despeje metade da massa em uma forma untada e adicione o recheio sobre ela. Cubra com o restante de massa e o queijo ralado. Leve ao forno preaquecido (180° C) até dourar. | E11: https://www.tudogostoso.com.br/receita/1282-torta-de-frango.html
A12: 10 | B12: Danoninho caseiro | C12: 1 lata de leite condensado 2 caixas de creme de leite 200 g de iogurte natural 1 pacote de suco em pó sabor morango | D12: Em um liquidificador, bata todos os ingrediente até obter uma consistência cremosa. Dispense a mistura em um recipiente e leve à geladeira até que esteja firme. | E12: https://www.tudogostoso.com.br/receita/19728-danoninho-caseiro.html
A13: 11 | B13: Brigadeiro | C13: 1 caixa de leite condensado 1 colher (sopa) de margarina sem sal 7 colheres (sopa) de achocolatado ou 4 colheres (sopa) de chocolate em pó chocolate granulado | D13: Em uma panela funda, acrescente o leite condensado, a margarina e o chocolate em pó. Cozinhe em fogo médio e mexa até que o brigadeiro comece a desgrudar da panela. Deixe esfriar efaça pequenas bolascom a mão passando a massa no chocolate granulado. | E13: https://www.tudogostoso.com.br/receita/114-brigadeiro.html
... A136: 134 | B136: Mousse de chocolate | C136: 1 lata de leite condensado 1 colher (chá) de manteiga ou margarina 1 lata de creme de leite gelado 3 claras em neve 4 colheres de achocolatado em pó | D136: Leve ao fogo o leite condensado, a manteiga e o achocolatado, mexendo sem parar até que a mistura solte do fundo da panela. Reserve e deixa esfriar. Misture o creme de leite e as claras em neve até obter uma mistura homogênea. Despeje a massa em um refratário e leve ao congelador por aproximadamente 50 minutos. Sirva bem gelado. | E136: https://www.tudogostoso.com.br/receita/1117-mousse-de-chocolate.html
A139: Top 50 | E139: Top 100
B140: Ingridient | C140: Quantity | F140: Ingridient | G140: Quantity
A141: 8 | B141: leite | C141: 41 | E141: 8 | F141: leite | G141: 65
A142: 3 | B142: açúcar | C142: 37 | E142: 3 | F142: açúcar | G142: 62
A143: 2 | B143: ovo | C143: 36 | E143: 2 | F143: ovo | G143: 62
A144: 4 | B144: farinha de trigo | C144: 35 | E144: 4 | F144: farinha de trigo | G144: 58
A145: 5 | B145: fermento | C145: 27 | E145: 5 | F145: fermento | G145: 40
A146: 0 | B146: óleo | C146: 24 | E146: 16 | F146: sal | G146: 40
A147: 7 | B147: chocolate | C147: 21 | E147: 0 | F147: óleo | G147: 36
A148: 16 | B148: sal | C148: 20 | E148: 7 | F148: chocolate | G148: 34
A149: 17 | B149: creme de leite | C149: 16 | E149: 28 | F149: margarina | G149: 31
A150: 29 | B150: margarina | C150: 16 | E150: 19 | F150: queijo | G150: 28
A151: 13 | B151: queijo | C151: 15 | E151: 17 | F151: creme de leite | G151: 27
A152: 11 | B152: leite condensado | C152: 14 | E152: 11 | F152: leite condensado | G152: 25
... A200: 59 | B200: farinha de rosca | C200: 1 | E200: 48 | F200: palmito | G200: 1
E201: 49 | F201: caldo legume | G201: 1
E202: 57 | F202: flocão de milho | G202: 1
E203: 58 | F203: pinga | G203: 1
E204: 61 | F204: farinha de rosca | G204: 1
E205: 67 | F205: couve manteiga | G205: 1
E206: 68 | F206: porco | G206: 1
E207: 72 | F207: maçã | G207: 1
E208: 73 | F208: goiabada | G208: 1
E209: 74 | F209: erva-doce | G209: 1
E210: 77 | F210: amendoim | G210: 1
E211: 78 | F211: caldo de galinha | G211: 1
...

Sheet English
A1: Id | B1: =IFERROR(__xludf.DUMMYFUNCTION("GOOGLETRANSLATE(Portuguese!B1,""pt"",""en"")"),"title") -> title | C1: =IFERROR(__xludf.DUMMYFUNCTION("GOOGLETRANSLATE(Portuguese!C1,""pt"",""en"")"),"ingredients") -> ingredients | D1: =IFERROR(__xludf.DUMMYFUNCTION("GOOGLETRANSLATE(Portuguese!D1,""pt"",""en"")"),"preparation") -> preparation | E1: Link
A2: 0 | B2: =IFERROR(__xludf.DUMMYFUNCTION("GOOGLETRANSLATE(Portuguese!B2,""pt"",""en"")"),"Carrot cake") -> Carrot cake | C2: =IFERROR(__xludf.DUMMYFUNCTION("GOOGLETRANSLATE(Portuguese!C2,""pt"",""en"")"),"1/2 cup (tea) of oil 3 medium grated carrots 4 eggs 2 cups (tea) of sugar 2 and 1/2 cups (tea) of wheat flour 1 tablespoon of baking powder 1 tablespoon of butter 3 tablespoons of cocoa powder 1 cup (tea) of sugar 1 cup (tea) of milk") -> 1/2 cup (tea) of oil 3 medium grated carrots 4 eggs 2 cups (tea) of sugar 2 and 1/2 cups (tea) of wheat flour 1 tablespoon of baking powder 1 tablespoon of butter 3 tablespoons of cocoa powder 1 cup (tea) of sugar 1 cup (tea) of milk | D2: =IFERROR(__xludf.DUMMYFUNCTION("GOOGLETRANSLATE(Portuguese!D2,""pt"",""en"")"),"In a blender, add the carrot, eggs, and oil, then blend. Add the sugar and blend again for 5 minutes. In a bowl or stand mixer, add the flour and then mix again. Add the baking powder and mix slowly with a spoon. Bake in a preheated oven at 180°C (350°F) "&"for approximately 40 minutes. Pour the butter, cocoa powder, sugar, and milk into a bowl, then mix. Bring the mixture to a boil and continue stirring until it reaches a creamy consistency, then pour the syrup over the cake.") -> In a blender, add the carrot, eggs, and oil, then blend. Add the sugar and blend again for 5 minutes. In a bowl or stand mixer, add the flour and then mix again. Add the baking powder and mix slowly with a spoon. Bake in a preheated oven at 180°C (350°F) for approximately 40 minutes. Pour the butter, cocoa powder, sugar, and milk into a bowl, then mix. Bring the mixture to a boil and continue stirring until it reaches a creamy consistency, then pour the syrup over the cake. | E2: https://www.tudogostoso.com.br/receita/23-bolo-de-cenoura.html
A3: 1 | B3: =IFERROR(__xludf.DUMMYFUNCTION("GOOGLETRANSLATE(Portuguese!B3,""pt"",""en"")"),"Iced cake") -> Iced cake | C3: =IFERROR(__xludf.DUMMYFUNCTION("GOOGLETRANSLATE(Portuguese!C3,""pt"",""en"")"),"4 eggs 2 cups of sugar 3 cups of wheat flour 1 glass of orange juice 1 tablespoon of baking powder 1 small bottle of coconut milk 1 bottle of milk (use the same bottle as the coconut milk for measuring) 1 can of condensed milk 1 packet of unsweete"&"ned shredded coconut") -> 4 eggs 2 cups of sugar 3 cups of wheat flour 1 glass of orange juice 1 tablespoon of baking powder 1 small bottle of coconut milk 1 bottle of milk (use the same bottle as the coconut milk for measuring) 1 can of condensed milk 1 packet of unsweetened shredded coconut | D3: =IFERROR(__xludf.DUMMYFUNCTION("GOOGLETRANSLATE(Portuguese!D3,""pt"",""en"")"),"In a mixer, beat the egg whites until stiff peaks form, gradually adding the sugar, and beat for 3 minutes. Add the egg yolks, flour, and juice, and continue beating until a smooth batter forms. Finally, add the baking powder and beat for another 40 secon"&"ds on the lowest speed of the mixer. Pour the batter into a greased medium-sized baking pan. Bake in a preheated oven at 180°C (350°F) for 40 minutes, or until golden brown. In a bowl, mix the coconut milk, milk, and condensed milk, and set aside. After 4"&"0 minutes, remove the cake from the oven and prick the entire surface with a fork to facilitate the penetration of the topping. While the cake is still warm, pour the topping over it and sprinkle with grated coconut. Refrigerate for 3 hours, then cut the "&"cake into squares of your preferred size and wrap in aluminum foil. Keep refrigerated.") -> In a mixer, beat the egg whites until stiff peaks form, gradually adding the sugar, and beat for 3 minutes. Add the egg yolks, flour, and juice, and continue beating until a smooth batter forms. Finally, add the baking powder and beat for another 40 seconds on the lowest speed of the mixer. Pour the batter into a greased medium-sized baking pan. Bake in a preheated oven at 180°C (350°F) for 40 minutes, or until golden brown. In a bowl, mix the coconut milk, milk, and condensed milk, and set aside. After 40 minutes, remove the cake from the oven and prick the entire surface with a fork to facilitate the penetration of the topping. While the cake is still warm, pour the topping over it and sprinkle with grated coconut. Refrigerate for 3 hours, then cut the cake into squares of your preferred size and wrap in aluminum foil. Keep refrigerated. | E3: https://www.tudogostoso.com.br/receita/2313-bolo-gelado.html
A4: 2 | B4: =IFERROR(__xludf.DUMMYFUNCTION("GOOGLETRANSLATE(Portuguese!B4,""pt"",""en"")"),"Blender cake") -> Blender cake | C4: =IFERROR(__xludf.DUMMYFUNCTION("GOOGLETRANSLATE(Portuguese!C4,""pt"",""en"")"),"1 egg 6 tablespoons of wheat flour 5 tablespoons of grated cheese 1 pinch of oregano 1 dessert spoon of baking powder 1/2 onion 1 cup of milk 1/2 cup of oil 1 pinch of salt") -> 1 egg 6 tablespoons of wheat flour 5 tablespoons of grated cheese 1 pinch of oregano 1 dessert spoon of baking powder 1/2 onion 1 cup of milk 1/2 cup of oil 1 pinch of salt | D4: =IFERROR(__xludf.DUMMYFUNCTION("GOOGLETRANSLATE(Portuguese!D4,""pt"",""en"")"),"Blend all ingredients in a blender until the batter is firm and thick. For a thicker batter, add another portion of wheat flour. Grease a baking pan with oil and pour half of the batter to cover the entire bottom. Then, add a filling of your choice and co"&"ver with the remaining batter. Bake in a preheated medium oven (180°C) for 30 minutes.") -> Blend all ingredients in a blender until the batter is firm and thick. For a thicker batter, add another portion of wheat flour. Grease a baking pan with oil and pour half of the batter to cover the entire bottom. Then, add a filling of your choice and cover with the remaining batter. Bake in a preheated medium oven (180°C) for 30 minutes. | E4: https://www.tudogostoso.com.br/receita/1362-torta-de-liquidificador.html
A5: 3 | B5: =IFERROR(__xludf.DUMMYFUNCTION("GOOGLETRANSLATE(Portuguese!B5,""pt"",""en"")"),"Chicken Fricassee") -> Chicken Fricassee | C5: =IFERROR(__xludf.DUMMYFUNCTION("GOOGLETRANSLATE(Portuguese!C5,""pt"",""en"")"),"1 can of heavy cream 1 can of sweet corn 1 cup of creamy cream cheese 100g pitted olives 2 shredded chicken breasts 200g sliced ​​mozzarella cheese 100g potato sticks 1 cup of water 1 pinch of salt") -> 1 can of heavy cream 1 can of sweet corn 1 cup of creamy cream cheese 100g pitted olives 2 shredded chicken breasts 200g sliced ​​mozzarella cheese 100g potato sticks 1 cup of water 1 pinch of salt | D5: =IFERROR(__xludf.DUMMYFUNCTION("GOOGLETRANSLATE(Portuguese!D5,""pt"",""en"")"),"Blend the corn, cream cheese, heavy cream, and water in a blender. Sauté the blended mixture with the shredded chicken, olives, and salt until it thickens. Place the mixture in a baking dish, cover with mozzarella cheese, and sprinkle potato sticks on to"&"p. Bake until bubbly. Serve with white rice.") -> Blend the corn, cream cheese, heavy cream, and water in a blender. Sauté the blended mixture with the shredded chicken, olives, and salt until it thickens. Place the mixture in a baking dish, cover with mozzarella cheese, and sprinkle potato sticks on top. Bake until bubbly. Serve with white rice. | E5: https://www.tudogostoso.com.br/receita/10254-fricasse-de-frango.html
A6: 4 | B6: =IFERROR(__xludf.DUMMYFUNCTION("GOOGLETRANSLATE(Portuguese!B6,""pt"",""en"")"),"Moist chocolate cake") -> Moist chocolate cake | C6: =IFERROR(__xludf.DUMMYFUNCTION("GOOGLETRANSLATE(Portuguese!C6,""pt"",""en"")"),"2 cups all-purpose flour 2 cups sugar 1 cup milk 6 tablespoons cocoa powder 1 tablespoon baking powder 6 eggs Topping 2 tablespoons butter 2 cups milk 1 cup cocoa powder") -> 2 cups all-purpose flour 2 cups sugar 1 cup milk 6 tablespoons cocoa powder 1 tablespoon baking powder 6 eggs Topping 2 tablespoons butter 2 cups milk 1 cup cocoa powder | D6: =IFERROR(__xludf.DUMMYFUNCTION("GOOGLETRANSLATE(Portuguese!D6,""pt"",""en"")"),"In a mixer, beat the egg whites until stiff peaks form. Add the egg yolks and sugar and beat again. Add the flour, cocoa powder, baking powder, and milk and beat for a few more minutes. Pour the batter into a greased pan and bake in a preheated medium ove"&"n (180°C) for 40 minutes. In a saucepan, heat the cocoa powder, butter, and milk over medium heat until boiling. Pour the hot mixture over the baked cake.") -> In a mixer, beat the egg whites until stiff peaks form. Add the egg yolks and sugar and beat again. Add the flour, cocoa powder, baking powder, and milk and beat for a few more minutes. Pour the batter into a greased pan and bake in a preheated medium oven (180°C) for 40 minutes. In a saucepan, heat the cocoa powder, butter, and milk over medium heat until boiling. Pour the hot mixture over the baked cake. | E6: https://www.tudogostoso.com.br/receita/951-bolo-de-chocolate-molhadinho.html
A7: 5 | B7: =IFERROR(__xludf.DUMMYFUNCTION("GOOGLETRANSLATE(Portuguese!B7,""pt"",""en"")"),"Ground beef pancake") -> Ground beef pancake | C7: =IFERROR(__xludf.DUMMYFUNCTION("GOOGLETRANSLATE(Portuguese!C7,""pt"",""en"")"),"1 1/2 cups (tea) of wheat flour 1 cup (tea) of milk 2 eggs 4 tablespoons of oil Salt to taste 300g of ground beef 2 tablespoons of chopped or grated onion 1/2 tomato, diced 1/2 can of tomato paste 1 carton of heavy cream Salt to taste 400g of sliced ​​moz"&"zarella cheese Grated cheese to taste") -> 1 1/2 cups (tea) of wheat flour 1 cup (tea) of milk 2 eggs 4 tablespoons of oil Salt to taste 300g of ground beef 2 tablespoons of chopped or grated onion 1/2 tomato, diced 1/2 can of tomato paste 1 carton of heavy cream Salt to taste 400g of sliced ​​mozzarella cheese Grated cheese to taste | D7: =IFERROR(__xludf.DUMMYFUNCTION("GOOGLETRANSLATE(Portuguese!D7,""pt"",""en"")"),"In a blender, beat together the eggs, milk, and oil, gradually adding the wheat flour. After adding all the wheat flour, add salt to taste. Mix the batter until you obtain a creamy consistency. Using a paper towel, spread oil all over the skillet and pour"&" in a ladleful of batter. Make circular motions so that the batter spreads throughout the skillet. Wait until the batter releases from the bottom and flip it to fry on the other side. In a saucepan, sauté the onion in oil and add the meat. Cook until the "&"meat releases its juices, then reduce the heat and cover. Add the chopped tomato and cover again. Cook for another 3 minutes and stir. Add the tomato paste and seasonings to taste. Cook for another 10 minutes. When the sauce thickens, turn off the heat. L"&"et the sauce cool, add the cream, and mix well. Once well combined, return to the heat and cook over low heat for another 5 minutes. Fill the pancake with a slice of mozzarella, a portion of meat, and roll it up. Repeat this process with all the pancakes"&". Pour some broth into the bottom of a baking dish to grease it. Arrange the prepared pancakes in the baking dish and pour the remaining sauce over them. Sprinkle grated cheese over the pancakes. Bake in a preheated oven at medium heat for 20 minutes, or "&"until the cheese is melted and golden brown.") -> In a blender, beat together the eggs, milk, and oil, gradually adding the wheat flour. After adding all the wheat flour, add salt to taste. Mix the batter until you obtain a creamy consistency. Using a paper towel, spread oil all over the skillet and pour in a ladleful of batter. Make circular motions so that the batter spreads throughout the skillet. Wait until the batter releases from the bottom and flip it to fry on the other side. In a saucepan, sauté the onion in oil and add the meat. Cook until the meat releases its juices, then reduce the heat and cover. Add the chopped tomato and cover again. Cook for another 3 minutes and stir. Add the tomato paste and seasonings to taste. Cook for another 10 minutes. When the sauce thickens, turn off the heat. Let the sauce cool, add the cream, and mix well. Once well combined, return to the heat and cook over low heat for another 5 minutes. Fill the pancake with a slice of mozzarella, a portion of meat, and roll it up. Repeat this process with all the pancakes. Pour some broth into the bottom of a baking dish to grease it. Arrange the prepared pancakes in the baking dish and pour the remaining sauce over them. Sprinkle grated cheese over the pancakes. Bake in a preheated oven at medium heat for 20 minutes, or until the cheese is melted and golden brown. | E7: https://www.tudogostoso.com.br/receita/760-panqueca-de-carne-moida.html
A8: 6 | B8: =IFERROR(__xludf.DUMMYFUNCTION("GOOGLETRANSLATE(Portuguese!B8,""pt"",""en"")"),"Simple condensed milk pudding") -> Simple condensed milk pudding | C8: =IFERROR(__xludf.DUMMYFUNCTION("GOOGLETRANSLATE(Portuguese!C8,""pt"",""en"")"),"1 can of sweetened condensed milk 1 cup of cow's milk 4 whole eggs 1 cup of sugar 1/3 cup of water") -> 1 can of sweetened condensed milk 1 cup of cow's milk 4 whole eggs 1 cup of sugar 1/3 cup of water | D8: =IFERROR(__xludf.DUMMYFUNCTION("GOOGLETRANSLATE(Portuguese!D8,""pt"",""en"")"),"In a saucepan, mix the water and sugar until a syrup forms. Grease a mold with the syrup and set aside. Blend all the ingredients in a blender and pour into the caramelized mold. Bake in a water bath for 40 minutes. Unmold and serve.") -> In a saucepan, mix the water and sugar until a syrup forms. Grease a mold with the syrup and set aside. Blend all the ingredients in a blender and pour into the caramelized mold. Bake in a water bath for 40 minutes. Unmold and serve. | E8: https://www.tudogostoso.com.br/receita/3687-pudim-de-leite-condensado.html
A9: 7 | B9: =IFERROR(__xludf.DUMMYFUNCTION("GOOGLETRANSLATE(Portuguese!B9,""pt"",""en"")"),"Simple cake") -> Simple cake | C9: =IFERROR(__xludf.DUMMYFUNCTION("GOOGLETRANSLATE(Portuguese!C9,""pt"",""en"")"),"2 cups (tea) of sugar 3 cups (tea) of wheat flour 4 tablespoons of margarine 3 eggs 1 and 1/2 cups (tea) of milk 1 heaping tablespoon of baking powder") -> 2 cups (tea) of sugar 3 cups (tea) of wheat flour 4 tablespoons of margarine 3 eggs 1 and 1/2 cups (tea) of milk 1 heaping tablespoon of baking powder | D9: =IFERROR(__xludf.DUMMYFUNCTION("GOOGLETRANSLATE(Portuguese!D9,""pt"",""en"")"),"Beat the egg whites until stiff peaks form and set aside. Mix the egg yolks, margarine, and sugar until you obtain a homogeneous mixture. Gradually add the milk and wheat flour, continuing to beat. Finally, add the beaten egg whites and the baking powd"&"er. Pour the batter into a large, greased and floured bundt pan. Bake in a preheated medium oven (180°C) for approximately 40 minutes, or until a fork inserted into the center comes out clean.") -> Beat the egg whites until stiff peaks form and set aside. Mix the egg yolks, margarine, and sugar until you obtain a homogeneous mixture. Gradually add the milk and wheat flour, continuing to beat. Finally, add the beaten egg whites and the baking powder. Pour the batter into a large, greased and floured bundt pan. Bake in a preheated medium oven (180°C) for approximately 40 minutes, or until a fork inserted into the center comes out clean. | E9: https://www.tudogostoso.com.br/receita/29124-bolo-simples.html
A10: 8 | B10: =IFERROR(__xludf.DUMMYFUNCTION("GOOGLETRANSLATE(Portuguese!B10,""pt"",""en"")"),"Fritter") -> Fritter | C10: =IFERROR(__xludf.DUMMYFUNCTION("GOOGLETRANSLATE(Portuguese!C10,""pt"",""en"")"),"2 eggs 2 tablespoons of sugar 1 cup of milk 2 1/2 cups of wheat flour 1 tablespoon of baking powder 3 tablespoons of sugar 1 teaspoon of cinnamon") -> 2 eggs 2 tablespoons of sugar 1 cup of milk 2 1/2 cups of wheat flour 1 tablespoon of baking powder 3 tablespoons of sugar 1 teaspoon of cinnamon | D10: =IFERROR(__xludf.DUMMYFUNCTION("GOOGLETRANSLATE(Portuguese!D10,""pt"",""en"")"),"In a bowl, add the eggs, sugar, milk, wheat flour, and baking powder, then mix them until you obtain a smooth and homogeneous dough. With the help of a spoon, take portions of the mixture and drop them into a pan with hot oil. Remove from the heat when it"&"'s ready, then mix the cinnamon with sugar and sprinkle it on the already fried fritters.") -> In a bowl, add the eggs, sugar, milk, wheat flour, and baking powder, then mix them until you obtain a smooth and homogeneous dough. With the help of a spoon, take portions of the mixture and drop them into a pan with hot oil. Remove from the heat when it's ready, then mix the cinnamon with sugar and sprinkle it on the already fried fritters. | E10: https://www.tudogostoso.com.br/receita/4683-bolinho-de-chuva.html
A11: 9 | B11: =IFERROR(__xludf.DUMMYFUNCTION("GOOGLETRANSLATE(Portuguese!B11,""pt"",""en"")"),"Chicken pie") -> Chicken pie | C11: =IFERROR(__xludf.DUMMYFUNCTION("GOOGLETRANSLATE(Portuguese!C11,""pt"",""en"")"),"500g skinless chicken breast 1/2 liter chicken broth 4 tablespoons oil 1 clove garlic, crushed 1 onion, chopped 3 tomatoes, peeled and seeded 1 cup peas Salt to taste Black pepper to taste 250ml milk 3/4 cup oil 2 eggs 1 1/2 cups all-purpose flour Salt to"&" taste 1 tablespoon baking powder Grated cheese to taste") -> 500g skinless chicken breast 1/2 liter chicken broth 4 tablespoons oil 1 clove garlic, crushed 1 onion, chopped 3 tomatoes, peeled and seeded 1 cup peas Salt to taste Black pepper to taste 250ml milk 3/4 cup oil 2 eggs 1 1/2 cups all-purpose flour Salt to taste 1 tablespoon baking powder Grated cheese to taste | D11: =IFERROR(__xludf.DUMMYFUNCTION("GOOGLETRANSLATE(Portuguese!D11,""pt"",""en"")"),"Cook the chicken breast in the broth until tender. Set aside 1 cup of the cooking broth. Sauté the remaining ingredients and add the peas last. Shred the chicken, mix it with the broth, and cook until the liquid evaporates. Blend the milk, oil, and eggs i"&"n a blender on low speed. Gradually add the flour, salt, and baking powder. Pour half of the batter into a greased baking dish and add the filling on top. Cover with the remaining batter and grated cheese. Bake in a preheated oven (180°C) until golden bro"&"wn.") -> Cook the chicken breast in the broth until tender. Set aside 1 cup of the cooking broth. Sauté the remaining ingredients and add the peas last. Shred the chicken, mix it with the broth, and cook until the liquid evaporates. Blend the milk, oil, and eggs in a blender on low speed. Gradually add the flour, salt, and baking powder. Pour half of the batter into a greased baking dish and add the filling on top. Cover with the remaining batter and grated cheese. Bake in a preheated oven (180°C) until golden brown. | E11: https://www.tudogostoso.com.br/receita/1282-torta-de-frango.html
A12: 10 | B12: =IFERROR(__xludf.DUMMYFUNCTION("GOOGLETRANSLATE(Portuguese!B12,""pt"",""en"")"),"Homemade Danoninho") -> Homemade Danoninho | C12: =IFERROR(__xludf.DUMMYFUNCTION("GOOGLETRANSLATE(Portuguese!C12,""pt"",""en"")"),"1 can of sweetened condensed milk 2 cartons of heavy cream 200g of natural yogurt 1 packet of strawberry-flavored powdered juice") -> 1 can of sweetened condensed milk 2 cartons of heavy cream 200g of natural yogurt 1 packet of strawberry-flavored powdered juice | D12: =IFERROR(__xludf.DUMMYFUNCTION("GOOGLETRANSLATE(Portuguese!D12,""pt"",""en"")"),"In a blender, blend all ingredients until creamy. Pour the mixture into a container and refrigerate until firm.") -> In a blender, blend all ingredients until creamy. Pour the mixture into a container and refrigerate until firm. | E12: https://www.tudogostoso.com.br/receita/19728-danoninho-caseiro.html
A13: 11 | B13: =IFERROR(__xludf.DUMMYFUNCTION("GOOGLETRANSLATE(Portuguese!B13,""pt"",""en"")"),"Brigadier") -> Brigadier | C13: =IFERROR(__xludf.DUMMYFUNCTION("GOOGLETRANSLATE(Portuguese!C13,""pt"",""en"")"),"1 can of sweetened condensed milk 1 tablespoon of unsalted margarine 7 tablespoons of chocolate powder or 4 tablespoons of cocoa powder chocolate sprinkles") -> 1 can of sweetened condensed milk 1 tablespoon of unsalted margarine 7 tablespoons of chocolate powder or 4 tablespoons of cocoa powder chocolate sprinkles | D13: =IFERROR(__xludf.DUMMYFUNCTION("GOOGLETRANSLATE(Portuguese!D13,""pt"",""en"")"),"In a deep saucepan, add the condensed milk, margarine, and cocoa powder. Cook over medium heat and stir until the brigadeiro starts to come away from the sides of the pan. Let it cool and form small balls with your hands, rolling the dough in chocolate sp"&"rinkles.") -> In a deep saucepan, add the condensed milk, margarine, and cocoa powder. Cook over medium heat and stir until the brigadeiro starts to come away from the sides of the pan. Let it cool and form small balls with your hands, rolling the dough in chocolate sprinkles. | E13: https://www.tudogostoso.com.br/receita/114-brigadeiro.html
A14: 12 | B14: =IFERROR(__xludf.DUMMYFUNCTION("GOOGLETRANSLATE(Portuguese!B14,""pt"",""en"")"),"The best chocolate cake recipe") -> The best chocolate cake recipe | C14: =IFERROR(__xludf.DUMMYFUNCTION("GOOGLETRANSLATE(Portuguese!C14,""pt"",""en"")"),"4 eggs 4 tablespoons of cocoa powder 2 tablespoons of butter 3 cups of wheat flour 2 cups of sugar 2 tablespoons of baking powder 1 cup of milk 2 tablespoons of butter 7 tablespoons of cocoa powder 2 cans of heavy cream (with whey) 3 tablespoons o"&"f sugar") -> 4 eggs 4 tablespoons of cocoa powder 2 tablespoons of butter 3 cups of wheat flour 2 cups of sugar 2 tablespoons of baking powder 1 cup of milk 2 tablespoons of butter 7 tablespoons of cocoa powder 2 cans of heavy cream (with whey) 3 tablespoons of sugar | D14: =IFERROR(__xludf.DUMMYFUNCTION("GOOGLETRANSLATE(Portuguese!D14,""pt"",""en"")"),"In a blender, add the eggs, cocoa powder, butter, wheat flour, sugar, and milk, then blend for 5 minutes. Add the baking powder and gently mix with a spatula. In a greased pan, pour the batter and bake in a preheated medium oven (180 ºC) for about 40 minu"&"tes. Don't forget to use a tall pan for this recipe: since it uses two tablespoons of baking powder, it rises quite a bit! Another solution is to use only one tablespoon of baking powder and keep your recipe in a small pan. In a saucepan, heat the butter "&"and mix in the cocoa powder until smooth. Add the heavy cream and mix well until you obtain a creamy consistency. Turn off the heat and add the sugar.") -> In a blender, add the eggs, cocoa powder, butter, wheat flour, sugar, and milk, then blend for 5 minutes. Add the baking powder and gently mix with a spatula. In a greased pan, pour the batter and bake in a preheated medium oven (180 ºC) for about 40 minutes. Don't forget to use a tall pan for this recipe: since it uses two tablespoons of baking powder, it rises quite a bit! Another solution is to use only one tablespoon of baking powder and keep your recipe in a small pan. In a saucepan, heat the butter and mix in the cocoa powder until smooth. Add the heavy cream and mix well until you obtain a creamy consistency. Turn off the heat and add the sugar. | E14: https://www.tudogostoso.com.br/receita/62547-a-melhor-receita-de-bolo-de-chocolate.html
A15: 13 | B15: =IFERROR(__xludf.DUMMYFUNCTION("GOOGLETRANSLATE(Portuguese!B15,""pt"",""en"")"),"Pancakes (Grandma's recipe)") -> Pancakes (Grandma's recipe) | C15: =IFERROR(__xludf.DUMMYFUNCTION("GOOGLETRANSLATE(Portuguese!C15,""pt"",""en"")"),"1 cup of milk 1 egg 1 cup of wheat flour 1 tablespoon of oil 1 pinch of salt") -> 1 cup of milk 1 egg 1 cup of wheat flour 1 tablespoon of oil 1 pinch of salt | D15: =IFERROR(__xludf.DUMMYFUNCTION("GOOGLETRANSLATE(Portuguese!D15,""pt"",""en"")"),"Blend all ingredients in a blender until creamy. Grease a skillet with butter, wait for it to heat up, and pour in a ladleful of batter. Make circular motions so that the batter spreads across the entire skillet. Cook until the edges turn golden brown. Wa"&"it until the batter releases from the bottom, flip, and cook on the other side. Fill as desired, roll up, and serve.") -> Blend all ingredients in a blender until creamy. Grease a skillet with butter, wait for it to heat up, and pour in a ladleful of batter. Make circular motions so that the batter spreads across the entire skillet. Cook until the edges turn golden brown. Wait until the batter releases from the bottom, flip, and cook on the other side. Fill as desired, roll up, and serve. | E15: https://www.tudogostoso.com.br/receita/1316-panquecas-receita-da-vovo.html
A16: 14 | B16: =IFERROR(__xludf.DUMMYFUNCTION("GOOGLETRANSLATE(Portuguese!B16,""pt"",""en"")"),"Grandma Maria's cornmeal cake") -> Grandma Maria's cornmeal cake | C16: =IFERROR(__xludf.DUMMYFUNCTION("GOOGLETRANSLATE(Portuguese!C16,""pt"",""en"")"),"4 eggs 2 cups of sugar 2 cups of wheat flour 1 cup of cornmeal 3 tablespoons of margarine 1 cup of milk 4 teaspoons of baking powder") -> 4 eggs 2 cups of sugar 2 cups of wheat flour 1 cup of cornmeal 3 tablespoons of margarine 1 cup of milk 4 teaspoons of baking powder | D16: =IFERROR(__xludf.DUMMYFUNCTION("GOOGLETRANSLATE(Portuguese!D16,""pt"",""en"")"),"In a mixer, beat the egg whites until stiff peaks form and add the sugar. Add the egg yolks, margarine, milk, wheat flour, and cornmeal, and continue beating. Finally, add the baking powder and mix with a spoon or spatula. Pour the batter into a greased p"&"an and bake in a preheated medium oven (180°C) for approximately 30 minutes.") -> In a mixer, beat the egg whites until stiff peaks form and add the sugar. Add the egg yolks, margarine, milk, wheat flour, and cornmeal, and continue beating. Finally, add the baking powder and mix with a spoon or spatula. Pour the batter into a greased pan and bake in a preheated medium oven (180°C) for approximately 30 minutes. | E16: https://www.tudogostoso.com.br/receita/79-bolo-de-fuba-da-vo-maria.html
A17: 15 | B17: =IFERROR(__xludf.DUMMYFUNCTION("GOOGLETRANSLATE(Portuguese!B17,""pt"",""en"")"),"Creamy hot chocolate") -> Creamy hot chocolate | C17: =IFERROR(__xludf.DUMMYFUNCTION("GOOGLETRANSLATE(Portuguese!C17,""pt"",""en"")"),"2 cups of milk 1 tablespoon of cornstarch 3 tablespoons of cocoa powder 4 tablespoons of sugar 1 cinnamon stick 1 carton of heavy cream") -> 2 cups of milk 1 tablespoon of cornstarch 3 tablespoons of cocoa powder 4 tablespoons of sugar 1 cinnamon stick 1 carton of heavy cream | D17: =IFERROR(__xludf.DUMMYFUNCTION("GOOGLETRANSLATE(Portuguese!D17,""pt"",""en"")"),"In a blender, combine the milk, cornstarch, cocoa powder, and sugar. Pour the mixture into a saucepan with the cinnamon stick and cook over low heat, stirring constantly until it boils. Turn off the heat, add the heavy cream, and stir well until you have "&"a smooth mixture. Remove the cinnamon stick and serve hot.") -> In a blender, combine the milk, cornstarch, cocoa powder, and sugar. Pour the mixture into a saucepan with the cinnamon stick and cook over low heat, stirring constantly until it boils. Turn off the heat, add the heavy cream, and stir well until you have a smooth mixture. Remove the cinnamon stick and serve hot. | E17: https://www.tudogostoso.com.br/receita/130871-chocolate-quente-cremoso.html
A18: 16 | B18: =IFERROR(__xludf.DUMMYFUNCTION("GOOGLETRANSLATE(Portuguese!B18,""pt"",""en"")"),"Creamy cornmeal cake") -> Creamy cornmeal cake | C18: =IFERROR(__xludf.DUMMYFUNCTION("GOOGLETRANSLATE(Portuguese!C18,""pt"",""en"")"),"4 eggs 4 cups of milk 3 cups of sugar 2 tablespoons of wheat flour 1 1/2 cups of cornmeal 2 tablespoons of margarine 100g of grated cheese 1 tablespoon of baking powder") -> 4 eggs 4 cups of milk 3 cups of sugar 2 tablespoons of wheat flour 1 1/2 cups of cornmeal 2 tablespoons of margarine 100g of grated cheese 1 tablespoon of baking powder | D18: =IFERROR(__xludf.DUMMYFUNCTION("GOOGLETRANSLATE(Portuguese!D18,""pt"",""en"")"),"In a blender, mix all the ingredients until you obtain a creamy consistency. Pour the batter into a greased and floured baking pan. Bake in a preheated medium oven (180°C) for 40 minutes. Serve cold.") -> In a blender, mix all the ingredients until you obtain a creamy consistency. Pour the batter into a greased and floured baking pan. Bake in a preheated medium oven (180°C) for 40 minutes. Serve cold. | E18: https://www.tudogostoso.com.br/receita/3468-bolo-de-fuba-cremoso.html
A19: 17 | B19: =IFERROR(__xludf.DUMMYFUNCTION("GOOGLETRANSLATE(Portuguese!B19,""pt"",""en"")"),"Quick lemon mousse") -> Quick lemon mousse | C19: =IFERROR(__xludf.DUMMYFUNCTION("GOOGLETRANSLATE(Portuguese!C19,""pt"",""en"")"),"1 can of sweetened condensed milk 1 can of heavy cream 1/2 cup (American) of pure lemon juice Lemon biscuit") -> 1 can of sweetened condensed milk 1 can of heavy cream 1/2 cup (American) of pure lemon juice Lemon biscuit | D19: =IFERROR(__xludf.DUMMYFUNCTION("GOOGLETRANSLATE(Portuguese!D19,""pt"",""en"")"),"In a blender, beat the condensed milk and heavy cream for 3 minutes. Gradually add the lemon juice and continue beating. Pour the mousse into a baking dish and refrigerate. When ready to serve, crush the chocolate wafer and sprinkle it on top of the mouss"&"e to decorate.") -> In a blender, beat the condensed milk and heavy cream for 3 minutes. Gradually add the lemon juice and continue beating. Pour the mousse into a baking dish and refrigerate. When ready to serve, crush the chocolate wafer and sprinkle it on top of the mousse to decorate. | E19: https://www.tudogostoso.com.br/receita/155693-mousse-de-limao-rapido.html
A20: 18 | B20: =IFERROR(__xludf.DUMMYFUNCTION("GOOGLETRANSLATE(Portuguese!B20,""pt"",""en"")"),"Easy blender pizza") -> Easy blender pizza | C20: =IFERROR(__xludf.DUMMYFUNCTION("GOOGLETRANSLATE(Portuguese!C20,""pt"",""en"")"),"1 cup (tea) of milk 1 egg 1 teaspoon of salt 1 teaspoon of sugar 1 tablespoon of margarine 1 and 1/2 cups (tea) of wheat flour 1 dessert spoon of baking powder 1/2 can of tomato sauce 250 g of coarsely grated mozzarella cheese 2 sliced ​​tomatoes chopped "&"olives oregano to taste") -> 1 cup (tea) of milk 1 egg 1 teaspoon of salt 1 teaspoon of sugar 1 tablespoon of margarine 1 and 1/2 cups (tea) of wheat flour 1 dessert spoon of baking powder 1/2 can of tomato sauce 250 g of coarsely grated mozzarella cheese 2 sliced ​​tomatoes chopped olives oregano to taste | D20: =IFERROR(__xludf.DUMMYFUNCTION("GOOGLETRANSLATE(Portuguese!D20,""pt"",""en"")"),"In a blender, beat together the milk, egg, salt, sugar, margarine, wheat flour, and baking powder until everything is well combined. Pour the batter into a pizza pan greased with margarine and bake in a preheated oven for 20 minutes. Remove from the oven "&"and pour over the tomato sauce. Cover the dough with grated mozzarella, tomato, and oregano to taste. Bake again until the mozzarella melts.") -> In a blender, beat together the milk, egg, salt, sugar, margarine, wheat flour, and baking powder until everything is well combined. Pour the batter into a pizza pan greased with margarine and bake in a preheated oven for 20 minutes. Remove from the oven and pour over the tomato sauce. Cover the dough with grated mozzarella, tomato, and oregano to taste. Bake again until the mozzarella melts. | E20: https://www.tudogostoso.com.br/receita/93498-pizza-de-liquidificador-facil.html
A21: 19 | B21: =IFERROR(__xludf.DUMMYFUNCTION("GOOGLETRANSLATE(Portuguese!B21,""pt"",""en"")"),"Frozen coconut and chocolate dessert") -> Frozen coconut and chocolate dessert | C21: =IFERROR(__xludf.DUMMYFUNCTION("GOOGLETRANSLATE(Portuguese!C21,""pt"",""en"")"),"1 can of sweetened condensed milk 800 ml of milk 200 g of grated coconut 1 and 1/2 tablespoons of cornstarch 1 pinch of salt 1 can of heavy cream 12 tablespoons of chocolate powder") -> 1 can of sweetened condensed milk 800 ml of milk 200 g of grated coconut 1 and 1/2 tablespoons of cornstarch 1 pinch of salt 1 can of heavy cream 12 tablespoons of chocolate powder | D21: =IFERROR(__xludf.DUMMYFUNCTION("GOOGLETRANSLATE(Portuguese!D21,""pt"",""en"")"),"In a saucepan, mix all ingredients and cook over low heat until a smooth cream forms. Pour the cream into a serving dish or individual portions and set aside. In a bowl, mix the heavy cream and chocolate powder well without heating. Pour the mixture over "&"the white cream and refrigerate. Serve chilled.") -> In a saucepan, mix all ingredients and cook over low heat until a smooth cream forms. Pour the cream into a serving dish or individual portions and set aside. In a bowl, mix the heavy cream and chocolate powder well without heating. Pour the mixture over the white cream and refrigerate. Serve chilled. | E21: https://www.tudogostoso.com.br/receita/140770-doce-gelado-de-coco-com-chocolate.html
A22: 20 | B22: =IFERROR(__xludf.DUMMYFUNCTION("GOOGLETRANSLATE(Portuguese!B22,""pt"",""en"")"),"Homemade bread") -> Homemade bread | C22: =IFERROR(__xludf.DUMMYFUNCTION("GOOGLETRANSLATE(Portuguese!C22,""pt"",""en"")"),"2 1/2 cups of warm water 2 tablespoons of sugar 1 tablespoon of salt 1 egg 1 cup of oil 1 kg of wheat flour 50 g of baker's yeast") -> 2 1/2 cups of warm water 2 tablespoons of sugar 1 tablespoon of salt 1 egg 1 cup of oil 1 kg of wheat flour 50 g of baker's yeast | D22: =IFERROR(__xludf.DUMMYFUNCTION("GOOGLETRANSLATE(Portuguese!D22,""pt"",""en"")"),"Mix the yeast and warm water, set aside. In a blender, beat the sugar, oil, salt, egg, and water with the yeast for a few minutes. Pour the mixture into a bowl and gradually add the wheat flour, mixing with your hands. Add wheat flour until the dough no l"&"onger sticks to your hands and let it rise for 1 hour. Divide the dough into portions and shape the loaves. Let rise again for 40 minutes. Bake for 30 minutes.") -> Mix the yeast and warm water, set aside. In a blender, beat the sugar, oil, salt, egg, and water with the yeast for a few minutes. Pour the mixture into a bowl and gradually add the wheat flour, mixing with your hands. Add wheat flour until the dough no longer sticks to your hands and let it rise for 1 hour. Divide the dough into portions and shape the loaves. Let rise again for 40 minutes. Bake for 30 minutes. | E22: https://www.tudogostoso.com.br/receita/9589-pao-caseiro.html
A23: 21 | B23: =IFERROR(__xludf.DUMMYFUNCTION("GOOGLETRANSLATE(Portuguese!B23,""pt"",""en"")"),"Quick blender banana cake") -> Quick blender banana cake | C23: =IFERROR(__xludf.DUMMYFUNCTION("GOOGLETRANSLATE(Portuguese!C23,""pt"",""en"")"),"3 eggs 2 cups of sugar 1 cup of milk 1/2 cup of oil 2 cups of wheat flour 1 tablespoon of baking powder 7 bananas 3/4 cup of sugar 1/2 cup of hot water") -> 3 eggs 2 cups of sugar 1 cup of milk 1/2 cup of oil 2 cups of wheat flour 1 tablespoon of baking powder 7 bananas 3/4 cup of sugar 1/2 cup of hot water | D23: =IFERROR(__xludf.DUMMYFUNCTION("GOOGLETRANSLATE(Portuguese!D23,""pt"",""en"")"),"In a saucepan, add the sugar and stir until melted. Pour in the hot water and stir until the sugar dissolves. Let it thicken until it reaches the consistency of syrup and set aside. In a blender, beat the eggs, sugar, oil, and milk. Gradually add the whea"&"t flour and continue beating until you obtain a smooth and homogeneous batter. Finally, add the baking powder and blend at the lowest speed of the blender. Grease a medium baking pan with margarine and flour. Pour in the caramel and the bananas cut length"&"wise. Bake in a preheated medium oven at 180°C (350°F) for approximately 30 minutes.") -> In a saucepan, add the sugar and stir until melted. Pour in the hot water and stir until the sugar dissolves. Let it thicken until it reaches the consistency of syrup and set aside. In a blender, beat the eggs, sugar, oil, and milk. Gradually add the wheat flour and continue beating until you obtain a smooth and homogeneous batter. Finally, add the baking powder and blend at the lowest speed of the blender. Grease a medium baking pan with margarine and flour. Pour in the caramel and the bananas cut lengthwise. Bake in a preheated medium oven at 180°C (350°F) for approximately 30 minutes. | E23: https://www.tudogostoso.com.br/receita/119737-bolo-de-banana-rapido-de-liquidificador.html
A24: 22 | B24: =IFERROR(__xludf.DUMMYFUNCTION("GOOGLETRANSLATE(Portuguese!B24,""pt"",""en"")"),"Lemon mousse") -> Lemon mousse | C24: =IFERROR(__xludf.DUMMYFUNCTION("GOOGLETRANSLATE(Portuguese!C24,""pt"",""en"")"),"1 can of sweetened condensed milk 1 can of heavy cream 1/2 cup of lemon juice (this juice is pure, without water, just squeeze the lemon)") -> 1 can of sweetened condensed milk 1 can of heavy cream 1/2 cup of lemon juice (this juice is pure, without water, just squeeze the lemon) | D24: =IFERROR(__xludf.DUMMYFUNCTION("GOOGLETRANSLATE(Portuguese!D24,""pt"",""en"")"),"Place the heavy cream (with the whey) and the sweetened condensed milk in a blender. Blend briefly, then gradually add the lemon juice. It will become quite thick; refrigerate.") -> Place the heavy cream (with the whey) and the sweetened condensed milk in a blender. Blend briefly, then gradually add the lemon juice. It will become quite thick; refrigerate. | E24: https://www.tudogostoso.com.br/receita/1621-mousse-de-limao.html
A25: 23 | B25: =IFERROR(__xludf.DUMMYFUNCTION("GOOGLETRANSLATE(Portuguese!B25,""pt"",""en"")"),"Prestige cake") -> Prestige cake | C25: =IFERROR(__xludf.DUMMYFUNCTION("GOOGLETRANSLATE(Portuguese!C25,""pt"",""en"")"),"3 eggs 1/2 cup (tea) of oil 1 cup (tea) of milk 1 cup (tea) of sugar 1 cup (tea) of cocoa powder 2 cups (tea) of wheat flour 1 tablespoon of baking powder Grated coconut to taste 1 bottle of coconut milk 1 cup (tea) of milk 3 tablespoons of sugar 1 can o"&"f condensed milk 1 tablespoon of margarine 100 g of grated coconut 3 tablespoons of margarine 8 tablespoons of sugar 2 tablespoons of cocoa powder 2 cups (tea) of milk") -> 3 eggs 1/2 cup (tea) of oil 1 cup (tea) of milk 1 cup (tea) of sugar 1 cup (tea) of cocoa powder 2 cups (tea) of wheat flour 1 tablespoon of baking powder Grated coconut to taste 1 bottle of coconut milk 1 cup (tea) of milk 3 tablespoons of sugar 1 can of condensed milk 1 tablespoon of margarine 100 g of grated coconut 3 tablespoons of margarine 8 tablespoons of sugar 2 tablespoons of cocoa powder 2 cups (tea) of milk | D25: =IFERROR(__xludf.DUMMYFUNCTION("GOOGLETRANSLATE(Portuguese!D25,""pt"",""en"")"),"In a blender, beat the eggs, oil, and milk for 3 minutes and set aside. In a bowl, mix the sugar, flour, baking powder, chocolate, and shredded coconut to taste. Pour this mixture over the blender mixture and stir until the batter is consistent. Pour the "&"batter into a greased pan and bake in a preheated medium oven for 30 minutes, or until a fork inserted into the center comes out clean. Let cool, cut in half, and set aside. In a bowl, mix the coconut milk, milk, and sugar and pour over the halved cake to"&" moisten it. In a saucepan, cook the condensed milk, margarine, and shredded coconut over low heat until it pulls away from the bottom of the pan. Cook the margarine, sugar, cocoa powder, and milk over low heat until it thickens. Prick the bottom of the c"&"ake with a fork and pour some of the syrup over it. Spread the filling over the bottom half of the cake. Place the other half of the cake on top of the filling. Cover the cake with the chocolate frosting. Refrigerate for 45 minutes.") -> In a blender, beat the eggs, oil, and milk for 3 minutes and set aside. In a bowl, mix the sugar, flour, baking powder, chocolate, and shredded coconut to taste. Pour this mixture over the blender mixture and stir until the batter is consistent. Pour the batter into a greased pan and bake in a preheated medium oven for 30 minutes, or until a fork inserted into the center comes out clean. Let cool, cut in half, and set aside. In a bowl, mix the coconut milk, milk, and sugar and pour over the halved cake to moisten it. In a saucepan, cook the condensed milk, margarine, and shredded coconut over low heat until it pulls away from the bottom of the pan. Cook the margarine, sugar, cocoa powder, and milk over low heat until it thickens. Prick the bottom of the cake with a fork and pour some of the syrup over it. Spread the filling over the bottom half of the cake. Place the other half of the cake on top of the filling. Cover the cake with the chocolate frosting. Refrigerate for 45 minutes. | E25: https://www.tudogostoso.com.br/receita/51484-bolo-prestigio.html
A26: 24 | B26: =IFERROR(__xludf.DUMMYFUNCTION("GOOGLETRANSLATE(Portuguese!B26,""pt"",""en"")"),"Quick and easy Brigadeirão") -> Quick and easy Brigadeirão | C26: =IFERROR(__xludf.DUMMYFUNCTION("GOOGLETRANSLATE(Portuguese!C26,""pt"",""en"")"),"1 can of sweetened condensed milk 1 carton of heavy cream 8 tablespoons of chocolate powder 3 eggs 1 tablespoon of unsalted margarine chocolate sprinkles") -> 1 can of sweetened condensed milk 1 carton of heavy cream 8 tablespoons of chocolate powder 3 eggs 1 tablespoon of unsalted margarine chocolate sprinkles | D26: =IFERROR(__xludf.DUMMYFUNCTION("GOOGLETRANSLATE(Portuguese!D26,""pt"",""en"")"),"Blend all ingredients in a blender for 5 minutes until creamy. Pour the batter into a microwave-safe bundt pan greased with margarine. Microwave for 10 minutes. Let the batter cool for 15 minutes and refrigerate for 1 hour. Unmold and decorate with chocol"&"ate sprinkles.") -> Blend all ingredients in a blender for 5 minutes until creamy. Pour the batter into a microwave-safe bundt pan greased with margarine. Microwave for 10 minutes. Let the batter cool for 15 minutes and refrigerate for 1 hour. Unmold and decorate with chocolate sprinkles. | E26: https://www.tudogostoso.com.br/receita/73135-brigadeirao-rapido-e-facil.html
A27: 25 | B27: =IFERROR(__xludf.DUMMYFUNCTION("GOOGLETRANSLATE(Portuguese!B27,""pt"",""en"")"),"Chicken Stroganoff") -> Chicken Stroganoff | C27: =IFERROR(__xludf.DUMMYFUNCTION("GOOGLETRANSLATE(Portuguese!C27,""pt"",""en"")"),"3 chicken breasts, cubed 1 clove of garlic, minced Salt to taste Black pepper to taste 1 onion, chopped 2 tablespoons of mayonnaise 1 tablespoon of butter 1/2 cup of ketchup 1/3 cup of mustard 1 cup of mushrooms 1 cup of heavy cream Potato sticks to taste") -> 3 chicken breasts, cubed 1 clove of garlic, minced Salt to taste Black pepper to taste 1 onion, chopped 2 tablespoons of mayonnaise 1 tablespoon of butter 1/2 cup of ketchup 1/3 cup of mustard 1 cup of mushrooms 1 cup of heavy cream Potato sticks to taste | D27: =IFERROR(__xludf.DUMMYFUNCTION("GOOGLETRANSLATE(Portuguese!D27,""pt"",""en"")"),"In a saucepan, combine the chicken, garlic, mayonnaise, salt, and pepper. In a large skillet, melt the butter and sauté the onion until golden brown. Add the seasoned chicken and cook until browned. Add the mushrooms, ketchup, and mustard. Fold in the cre"&"am and remove from the heat before it boils. Serve with white rice and potato sticks.") -> In a saucepan, combine the chicken, garlic, mayonnaise, salt, and pepper. In a large skillet, melt the butter and sauté the onion until golden brown. Add the seasoned chicken and cook until browned. Add the mushrooms, ketchup, and mustard. Fold in the cream and remove from the heat before it boils. Serve with white rice and potato sticks. | E27: https://www.tudogostoso.com.br/receita/2462-strogonoff-de-frango.html
A28: 26 | B28: =IFERROR(__xludf.DUMMYFUNCTION("GOOGLETRANSLATE(Portuguese!B28,""pt"",""en"")"),"Passion fruit mousse") -> Passion fruit mousse | C28: =IFERROR(__xludf.DUMMYFUNCTION("GOOGLETRANSLATE(Portuguese!C28,""pt"",""en"")"),"1 can of sweetened condensed milk 1 can of passion fruit juice (measured using the sweetened condensed milk can) 1 can of heavy cream (without whey)") -> 1 can of sweetened condensed milk 1 can of passion fruit juice (measured using the sweetened condensed milk can) 1 can of heavy cream (without whey) | D28: =IFERROR(__xludf.DUMMYFUNCTION("GOOGLETRANSLATE(Portuguese!D28,""pt"",""en"")"),"In a blender, combine the heavy cream, sweetened condensed milk, and concentrated passion fruit juice. In a bowl, pour the mixture and refrigerate for at least 4 hours.") -> In a blender, combine the heavy cream, sweetened condensed milk, and concentrated passion fruit juice. In a bowl, pour the mixture and refrigerate for at least 4 hours. | E28: https://www.tudogostoso.com.br/receita/1599-mousse-de-maracuja.html
A29: 27 | B29: =IFERROR(__xludf.DUMMYFUNCTION("GOOGLETRANSLATE(Portuguese!B29,""pt"",""en"")"),"Creamy corn cake") -> Creamy corn cake | C29: =IFERROR(__xludf.DUMMYFUNCTION("GOOGLETRANSLATE(Portuguese!C29,""pt"",""en"")"),"1 can of sweet corn 1 can of oil (using the corn can as a measure) 1 can of sugar (using the corn can as a measure) 1 can of cornmeal (using the corn can as a measure) 4 eggs 2 tablespoons of wheat flour 2 tablespoons of shredded coconut 1 1/2 teaspoons "&"of baking powder") -> 1 can of sweet corn 1 can of oil (using the corn can as a measure) 1 can of sugar (using the corn can as a measure) 1 can of cornmeal (using the corn can as a measure) 4 eggs 2 tablespoons of wheat flour 2 tablespoons of shredded coconut 1 1/2 teaspoons of baking powder | D29: =IFERROR(__xludf.DUMMYFUNCTION("GOOGLETRANSLATE(Portuguese!D29,""pt"",""en"")"),"In a blender, add the corn, oil, sugar, cornmeal, eggs, and wheat flour, then blend until creamy. Next, add the shredded coconut and baking powder, and mix again. Pour the batter into a greased baking pan and bake in a preheated medium oven at 180°C (350°"&"F) for 40 minutes.") -> In a blender, add the corn, oil, sugar, cornmeal, eggs, and wheat flour, then blend until creamy. Next, add the shredded coconut and baking powder, and mix again. Pour the batter into a greased baking pan and bake in a preheated medium oven at 180°C (350°F) for 40 minutes. | E29: https://www.tudogostoso.com.br/receita/94018-bolo-de-milho-cremoso.html
